<mujoco model="roarm_description">
  <compiler angle="radian" meshdir="meshes"/>

  <asset>
    <mesh name="base_link" content_type="model/stl" file="base_link.STL"/>
    <mesh name="link1" content_type="model/stl" file="link1.STL"/>
    <mesh name="link2" content_type="model/stl" file="link2.STL"/>
    <mesh name="link3" content_type="model/stl" file="link3.STL"/>
    <mesh name="gripper_link" content_type="model/stl" file="gripper_link.STL"/>
  </asset>

  <worldbody>
    <geom type="mesh" rgba="0.752941 0.752941 0.752941 1" mesh="base_link"/>
    <body name="link1" pos="0.01 0 0.123059">
      <inertial pos="-3.1156e-12 9.7024e-06 -0.0146667" quat="0.707433 0.70678 0 0" mass="0.0928888" diaginertia="6.09211e-05 4.88051e-05 2.53493e-05"/>
      <joint name="base_link_to_link1" pos="0 0 0" axis="0 0 -1" range="-3.1416 3.1416"/>
      <geom type="mesh" rgba="0.752941 0.752941 0.752941 1" mesh="link1"/>
      <body name="link2" quat="0.5 -0.5 -0.5 -0.5">
        <inertial pos="0.122021 6.61338e-05 -9.50311e-05" quat="0.498128 0.497925 0.50206 0.501871" mass="0.0895817" diaginertia="0.00035039 0.000333057 2.62492e-05"/>
        <joint name="link1_to_link2" pos="0 0 0" axis="0 0 -1" range="-1.5708 1.5708"/>
        <geom type="mesh" rgba="0.752941 0.752941 0.752941 1" mesh="link2"/>
        <body name="link3" pos="0.236815 0.0300024 0" quat="0.707107 0 0 0.707107">
          <inertial pos="-0.000762809 -0.11442 -0.000177275" quat="0.672045 0.673543 -0.217394 0.217796" mass="0.123009" diaginertia="0.000104224 0.000103898 1.46353e-05"/>
          <joint name="link2_to_link3" pos="0 0 0" axis="0 0 1" range="-1 3.1416"/>
          <geom type="mesh" rgba="0.752941 0.752941 0.752941 1" mesh="link3"/>
          <body name="gripper_link" pos="0.002906 -0.21599 -0.00066683" quat="0.499998 -0.5 0.500002 -0.5">
            <inertial pos="0.0288857 -0.000776842 -0.000779765" quat="0.526622 0.526622 0.471879 0.471879" mass="0.00365698" diaginertia="2.34478e-06 1.4718e-06 1.13696e-06"/>
            <joint name="link3_to_gripper_link" pos="0 0 0" axis="0 0 1" range="0 1.5"/>
            <geom type="mesh" rgba="0.219608 0.219608 0.219608 1" mesh="gripper_link"/>
          </body>
        </body>
      </body>
    </body>
  </worldbody>
</mujoco>
